<?xml version="1.0"?>
<robot name="quadruped">
  <material name="green">
        <color rgba="0 .8 .8 1"/>
  </material>

  <material name="blue">
        <color rgba="0 .0 1 1"/>
  </material>

  <material name="black">
        <color rgba="0 0 0 1"/>
  </material>

  <link name="torso">
    <visual>
      <geometry>
        <box size="0.1 0.1 0.05"/>
      </geometry>
      <origin xyz="0 0 0"/>
      <material name="green"/>
    </visual>

    <collision>
      <geometry>
        <box size="0.1 0.1 0.05"/>
      </geometry>
      <origin xyz="0 0 0"/>
    </collision>

    <inertial>
      <origin xyz="0 0 0"/>
      <mass value="1.5"/>
      <inertia ixx="1.0" ixy="0.0" ixz="0.0" iyy="1.0" iyz="0.0" izz="1.0"/>
    </inertial>
  </link>


  <!-- FL leg (1) /-->
    <link name="coxa_fl">
      <visual>
        <origin xyz=".0 .01 0.0" rpy="-1.5708 0 0" />
        <geometry>
          <cylinder radius="0.01" length="0.02"/>
        </geometry>
        <material name="black"/>
      </visual>

      <inertial>
        <origin xyz=".0 .01 0.0" rpy="-1.5708 0 0" />
        <mass value="0.1"/>
        <inertia ixx="1.0" ixy="0.0" ixz="0.0" iyy="1.0" iyz="0.0" izz="1.0"/>
      </inertial>
    </link>

    <link name="femur_fl">
      <visual>
        <origin xyz=".0 .05 0.0" rpy="-1.5708 0 0" />
        <geometry>
          <cylinder radius="0.01" length="0.1"/>
        </geometry>
        <material name="blue"/>
      </visual>

      <inertial>
        <origin xyz=".0 .05 0.0" rpy="-1.5708 0 0" />
        <mass value="0.1"/>
        <inertia ixx="1.0" ixy="0.0" ixz="0.0" iyy="1.0" iyz="0.0" izz="1.0"/>
      </inertial>
    </link>

    <link name="tibia_fl">
      <visual>
        <origin xyz=".0 .05 0.0" rpy="-1.5708 0 0" />
        <geometry>
          <cylinder radius="0.01" length="0.1"/>
        </geometry>
        <material name="black"/>
      </visual>

      <collision>
        <origin xyz=".0 .05 0.0" rpy="-1.5708 0 0" />
        <geometry>
          <cylinder radius="0.01" length="0.1"/>
        </geometry>
      </collision>

      <inertial>
        <origin xyz=".0 .05 0.0" rpy="-1.5708 0 0" />
        <mass value="0.1"/>
        <inertia ixx="1.0" ixy="0.0" ixz="0.0" iyy="1.0" iyz="0.0" izz="1.0"/>
      </inertial>
    </link>

    <joint name="torso_coxa_fl" type="revolute">
      <axis xyz="0 0 -1"/>
      <origin xyz="0.05 0.05 0"/>
      <parent link="torso"/>
      <child link="coxa_fl"/>
      <limit effort="100.0" lower="-3" upper="3" velocity="5"/>
      <dynamics damping="0.1" friction="0.1"/>
    </joint>

    <joint name="coxa_femur_fl" type="revolute">
      <axis xyz="-1 0 0"/>
      <origin xyz="0.0 0.01 0"/>
      <parent link="coxa_fl"/>
      <child link="femur_fl"/>
      <limit effort="100.0" lower="-3" upper="3" velocity="5"/>
      <dynamics damping="0.1" friction="0.1"/>
    </joint>

    <joint name="femur_tibia_fl" type="revolute">
      <axis xyz="-1 0 0"/>
      <origin xyz="0.0 0.10 0"/>
      <parent link="femur_fl"/>
      <child link="tibia_fl"/>
      <limit effort="100.0" lower="-3" upper="3" velocity="5"/>
      <dynamics damping="0.1" friction="0.1"/>
    </joint>

    <!-- FR leg (2) /-->
    <link name="coxa_fr">
      <visual>
        <origin xyz=".0 -.01 0.0" rpy="1.5708 0 0" />
        <geometry>
          <cylinder radius="0.01" length="0.02"/>
        </geometry>
        <material name="black"/>
      </visual>

      <inertial>
        <origin xyz=".0 -.01 0.0" rpy="1.5708 0 0" />
        <mass value="0.1"/>
        <inertia ixx="1.0" ixy="0.0" ixz="0.0" iyy="1.0" iyz="0.0" izz="1.0"/>
      </inertial>
    </link>

    <link name="femur_fr">
      <visual>
        <origin xyz=".0 -.05 0.0" rpy="1.5708 0 0" />
        <geometry>
          <cylinder radius="0.01" length="0.1"/>
        </geometry>
        <material name="blue"/>
      </visual>

      <inertial>
        <origin xyz=".0 -.05 0.0" rpy="1.5708 0 0" />
        <mass value="0.1"/>
        <inertia ixx="1.0" ixy="0.0" ixz="0.0" iyy="1.0" iyz="0.0" izz="1.0"/>
      </inertial>
    </link>

    <link name="tibia_fr">
      <visual>
        <origin xyz=".0 -.05 0.0" rpy="1.5708 0 0" />
        <geometry>
          <cylinder radius="0.01" length="0.1"/>
        </geometry>
        <material name="black"/>
      </visual>

      <collision>
        <origin xyz=".0 -.05 0.0" rpy="1.5708 0 0" />
        <geometry>
          <cylinder radius="0.01" length="0.1"/>
        </geometry>
      </collision>

      <inertial>
        <origin xyz=".0 -.05 0.0" rpy="1.5708 0 0" />
        <mass value="0.1"/>
        <inertia ixx="1.0" ixy="0.0" ixz="0.0" iyy="1.0" iyz="0.0" izz="1.0"/>
      </inertial>
    </link>

    <joint name="torso_coxa_fr" type="revolute">
      <axis xyz="0 0 1"/>
      <origin xyz="0.05 -0.05 0"/>
      <parent link="torso"/>
      <child link="coxa_fr"/>
      <limit effort="100.0" lower="-3" upper="3" velocity="5"/>
      <dynamics damping="0.1" friction="0.1"/>
    </joint>

    <joint name="coxa_femur_fr" type="revolute">
      <axis xyz="1 0 0"/>
      <origin xyz="0.0 -0.01 0"/>
      <parent link="coxa_fr"/>
      <child link="femur_fr"/>
      <limit effort="100.0" lower="-3" upper="3" velocity="5"/>
      <dynamics damping="0.1" friction="0.1"/>
    </joint>

    <joint name="femur_tibia_fr" type="revolute">
      <axis xyz="1 0 0"/>
      <origin xyz="0.0 -0.10 0"/>
      <parent link="femur_fr"/>
      <child link="tibia_fr"/>
      <limit effort="100.0" lower="-3" upper="3" velocity="5"/>
      <dynamics damping="0.1" friction="0.1"/>
    </joint>


    <!-- RL leg (3) /-->
    <link name="coxa_rl">
      <visual>
        <origin xyz=".0 .01 0.0" rpy="-1.5708 0 0" />
        <geometry>
          <cylinder radius="0.01" length="0.02"/>
        </geometry>
        <material name="black"/>
      </visual>

      <inertial>
        <origin xyz=".0 .01 0.0" rpy="-1.5708 0 0" />
        <mass value="0.1"/>
        <inertia ixx="1.0" ixy="0.0" ixz="0.0" iyy="1.0" iyz="0.0" izz="1.0"/>
      </inertial>
    </link>

    <link name="femur_rl">
      <visual>
        <origin xyz=".0 .05 0.0" rpy="-1.5708 0 0" />
        <geometry>
          <cylinder radius="0.01" length="0.1"/>
        </geometry>
        <material name="blue"/>
      </visual>

      <inertial>
        <origin xyz=".0 .05 0.0" rpy="-1.5708 0 0" />
        <mass value="0.1"/>
        <inertia ixx="1.0" ixy="0.0" ixz="0.0" iyy="1.0" iyz="0.0" izz="1.0"/>
      </inertial>
    </link>

    <link name="tibia_rl">
      <visual>
        <origin xyz=".0 .05 0.0" rpy="-1.5708 0 0" />
        <geometry>
          <cylinder radius="0.01" length="0.1"/>
        </geometry>
        <material name="black"/>
      </visual>

      <collision>
        <origin xyz=".0 .05 0.0" rpy="-1.5708 0 0" />
        <geometry>
          <cylinder radius="0.01" length="0.1"/>
        </geometry>
      </collision>

      <inertial>
        <origin xyz=".0 .05 0.0" rpy="-1.5708 0 0" />
        <mass value="0.1"/>
        <inertia ixx="1.0" ixy="0.0" ixz="0.0" iyy="1.0" iyz="0.0" izz="1.0"/>
      </inertial>
    </link>

    <joint name="torso_coxa_rl" type="revolute">
      <axis xyz="0 0 -1"/>
      <origin xyz="-0.05 0.05 0"/>
      <parent link="torso"/>
      <child link="coxa_rl"/>
      <limit effort="100.0" lower="-3" upper="3" velocity="5"/>
      <dynamics damping="0.1" friction="0.1"/>
    </joint>

    <joint name="coxa_femur_rl" type="revolute">
      <axis xyz="-1 0 0"/>
      <origin xyz="0.0 0.01 0"/>
      <parent link="coxa_rl"/>
      <child link="femur_rl"/>
      <limit effort="100.0" lower="-3" upper="3" velocity="5"/>
      <dynamics damping="0.1" friction="0.1"/>
    </joint>

    <joint name="femur_tibia_rl" type="revolute">
      <axis xyz="-1 0 0"/>
      <origin xyz="0.0 0.10 0"/>
      <parent link="femur_rl"/>
      <child link="tibia_rl"/>
      <limit effort="100.0" lower="-3" upper="3" velocity="5"/>
      <dynamics damping="0.1" friction="0.1"/>
    </joint>

  <!-- RR leg (4) /-->

    <link name="coxa_rr">
      <visual>
        <origin xyz=".0 -.01 0.0" rpy="1.5708 0 0" />
        <geometry>
          <cylinder radius="0.01" length="0.02"/>
        </geometry>
        <material name="black"/>
      </visual>

      <inertial>
        <origin xyz=".0 -.01 0.0" rpy="1.5708 0 0" />
        <mass value="0.1"/>
        <inertia ixx="1.0" ixy="0.0" ixz="0.0" iyy="1.0" iyz="0.0" izz="1.0"/>
      </inertial>
    </link>

    <link name="femur_rr">
      <visual>
        <origin xyz=".0 -.05 0.0" rpy="1.5708 0 0" />
        <geometry>
          <cylinder radius="0.01" length="0.1"/>
        </geometry>
        <material name="blue"/>
      </visual>

      <inertial>
        <origin xyz=".0 -.05 0.0" rpy="1.5708 0 0" />
        <mass value="0.1"/>
        <inertia ixx="1.0" ixy="0.0" ixz="0.0" iyy="1.0" iyz="0.0" izz="1.0"/>
      </inertial>
    </link>

    <link name="tibia_rr">
      <visual>
        <origin xyz=".0 -.05 0.0" rpy="1.5708 0 0" />
        <geometry>
          <cylinder radius="0.01" length="0.1"/>
        </geometry>
        <material name="black"/>
      </visual>

      <collision>
        <origin xyz=".0 -.05 0.0" rpy="1.5708 0 0" />
        <geometry>
          <cylinder radius="0.01" length="0.1"/>
        </geometry>
      </collision>

      <inertial>
        <origin xyz=".0 -.05 0.0" rpy="1.5708 0 0" />
        <mass value="0.1"/>
        <inertia ixx="1.0" ixy="0.0" ixz="0.0" iyy="1.0" iyz="0.0" izz="1.0"/>
      </inertial>
    </link>

    <joint name="torso_coxa_rr" type="revolute">
      <axis xyz="0 0 1"/>
      <origin xyz="-0.05 -0.05 0"/>
      <parent link="torso"/>
      <child link="coxa_rr"/>
      <limit effort="100.0" lower="-3" upper="3" velocity="5"/>
      <dynamics damping="0.1" friction="0.1"/>
    </joint>

    <joint name="coxa_femur_rr" type="revolute">
      <axis xyz="1 0 0"/>
      <origin xyz="0.0 -0.01 0"/>
      <parent link="coxa_rr"/>
      <child link="femur_rr"/>
      <limit effort="100.0" lower="-3" upper="3" velocity="5"/>
      <dynamics damping="0.1" friction="0.1"/>
    </joint>

    <joint name="femur_tibia_rr" type="revolute">
      <axis xyz="1 0 0"/>
      <origin xyz="0.0 -0.10 0"/>
      <parent link="femur_rr"/>
      <child link="tibia_rr"/>
      <limit effort="100.0" lower="-3" upper="3" velocity="5"/>
      <dynamics damping="0.1" friction="0.1"/>
    </joint>

  <contact_coefficients mu="0.5" />

</robot>